Workbook
Name mydata: 'Cleaned data'!$A$1:$Z$1201
Name Slicer_Adopter_Type: #N/A
Name Slicer_City: #N/A
Name Slicer_Color: #N/A
Name Slicer_Health_Status: #N/A
Name Slicer_Payment_Method: #N/A
Name Slicer_Species: #N/A

Sheet Raw data
A1: Animal_ID | B1: Shelter_Name | C1: City | D1: Species | E1: Breed | F1: Color | G1: Gender | H1: Age_Years | I1: Weight_KG | J1: Health_Status | K1: Intake_Date | L1: Intake_Reason | M1: Outcome_Date | N1: Outcome_Type | O1: Days_In_Shelter | P1: Adopter_Type | Q1: Adoption_Fee_PKR | R1: Donation_Amount_PKR | S1: Payment_Method | T1: Source_of_Inquiry | U1: Vaccinated | V1: Neutered_Spayed | W1: Microchipped | X1: Year | Y1: Month | Z1: Quarter
A2: A0001 | B2: Paws & Claws Rescue | C2: Lahore | D2: Cat | E2: Persian | F2: Spotted | G2: Female | H2: 8.9 | I2: 23.8 | J2: Healthy | K2: 2023-07-18 | L2: Stray | M2: 2023-09-19 | N2: Returned to Owner | O2: 63 | Q2: 0 | R2: 0 | T2: Walk-in | U2: Yes | V2: Yes | W2: Yes | X2: 2023 | Y2: July | Z2: Q3
A3: A0002 | B3: Second Chance Rescue | C3: Faisalabad | D3: Cat | E3: Siamese | F3: Black & White | G3: Female | H3: 9.7 | I3: 0.7 | J3: Healthy | K3: 2024-05-09 | L3: Owner Surrender | M3: 2024-07-05 | N3: Fostered | O3: 57 | Q3: 0 | R3: 500 | T3: Social Media | U3: Yes | V3: Yes | W3: No | X3: 2024 | Y3: May | Z3: Q2
A4: A0003 | B4: Paws & Claws Rescue | C4: Lahore | D4: Cat | E4: Bengal | F4: Tan | G4: Male | H4: 9.7 | I4: 25.7 | J4: Vaccinated | K4: 2023-12-06 | L4: Abandoned | M4: 2024-05-09 | N4: Transferred | O4: 155 | Q4: 0 | R4: 0 | T4: Event | U4: Yes | V4: No | W4: No | X4: 2023 | Y4: December | Z4: Q4
A5: A0004 | B5: Hope Animal Shelter | C5: Multan | D5: Cat | E5: Persian | F5: Brown | G5: Female | H5: 1.3 | I5: 10.1 | J5: Healthy | K5: 2023-04-12 | L5: Owner Surrender | M5: 2023-06-26 | N5: Adopted | O5: 75 | P5: Senior | Q5: 2453 | R5: 5000 | S5: Cash | T5: Event | U5: Yes | V5: No | W5: No | X5: 2023 | Y5: April | Z5: Q2
A6: A0005 | B6: Second Chance Rescue | C6: Islamabad | D6: Dog | E6: Husky | F6: Black & White | G6: Female | H6: 10.1 | I6: 27.3 | J6: Healthy | K6: 2024-02-17 | L6: Stray | M6: 2024-04-27 | N6: Returned to Owner | O6: 70 | Q6: 0 | R6: 500 | T6: Website | U6: Yes | V6: Yes | W6: No | X6: 2024 | Y6: February | Z6: Q1
A7: A0006 | B7: Paws & Claws Rescue | C7: Faisalabad | D7: Bird | E7: Lovebird | F7: Spotted | G7: Female | H7: 6.8 | I7: 9.6 | J7: Healthy | K7: 2022-10-20 | L7: Owner Surrender | M7: 2022-12-27 | N7: Adopted | O7: 68 | P7: Family | Q7: 1510 | R7: 2000 | S7: Bank Deposit | T7: Walk-in | U7: Yes | V7: Yes | W7: No | X7: 2022 | Y7: October | Z7: Q4
A8: A0007 | B8: City Animal Shelter | C8: Islamabad | D8: Dog | E8: Mixed Breed | F8: White | G8: Female | H8: 7.2 | I8: 16.6 | J8: Recovering | K8: 2022-05-11 | L8: Confiscated | M8: 2022-08-18 | N8: Still in Shelter | O8: 99 | Q8: 0 | R8: 0 | T8: Social Media | U8: Yes | V8: No | W8: No | X8: 2022 | Y8: May | Z8: Q2
A9: A0008 | B9: Hope Animal Shelter | C9: Peshawar | D9: Dog | E9: Husky | F9: Brown | G9: Female | H9: 10.5 | I9: 10.8 | J9: Recovering | K9: 2022-01-07 | L9: Owner Surrender | M9: 2022-03-16 | N9: Adopted | O9: 68 | P9: Couple | Q9: 7158 | R9: 0 | S9: Cash | T9: Event | U9: Yes | V9: No | W9: Yes | X9: 2022 | Y9: January | Z9: Q1
A10: A0009 | B10: Furever Home | C10: Lahore | D10: Cat | E10: Bengal | F10: Cream | G10: Male | H10: 11.4 | I10: 3.5 | J10: Healthy | K10: 2023-09-22 | L10: Confiscated | M10: 2023-11-23 | N10: Adopted | O10: 62 | P10: Single Adult | Q10: 2486 | R10: 1000 | S10: Card | T10: Social Media | U10: No | V10: Yes | W10: No | X10: 2023 | Y10: September | Z10: Q3
A11: A0010 | B11: Happy Paws Shelter | C11: Peshawar | D11: Cat | E11: Domestic Shorthair | F11: Spotted | G11: Male | H11: 3.1 | I11: 2.7 | J11: Healthy | K11: 2024-02-04 | L11: Stray | M11: 2024-05-27 | N11: Fostered | O11: 113 | Q11: 0 | R11: 0 | T11: Walk-in | U11: Yes | V11: Yes | W11: Yes | X11: 2024 | Y11: February | Z11: Q1
A12: A0011 | B12: Second Chance Rescue | C12: Rawalpindi | D12: Rabbit | E12: Holland Lop | F12: Golden | G12: Female | H12: 8.1 | I12: 7.9 | J12: Recovering | K12: 2024-11-18 | L12: Transfer from Another Shelter | M12: 2024-12-31 | N12: Transferred | O12: 61 | Q12: 0 | R12: 0 | T12: Website | U12: Yes | V12: Yes | W12: No | X12: 2024 | Y12: November | Z12: Q4
A13: A0012 | B13: Happy Paws Shelter | C13: Peshawar | D13: Rabbit | E13: Dutch | F13: Golden | G13: Male | H13: 4.9 | I13: 12.2 | J13: Vaccinated | K13: 2024-04-21 | L13: Transfer from Another Shelter | M13: 2024-08-19 | N13: Adopted | O13: 120 | P13: Family | Q13: 903 | R13: 0 | S13: Bank Deposit | T13: Website | U13: Yes | V13: No | W13: No | X13: 2024 | Y13: April | Z13: Q2
A14: A0013 | B14: Furever Home | C14: Rawalpindi | D14: Cat | E14: Domestic Shorthair | F14: Golden | G14: Female | H14: 10.2 | I14: 6.2 | J14: Healthy | K14: 2022-07-20 | L14: Owner Surrender | M14: 2022-08-02 | N14: Adopted | O14: 13 | P14: Single Adult | Q14: 1882 | R14: 5000 | S14: Cash | T14: Referral | U14: Yes | V14: No | W14: No | X14: 2022 | Y14: July | Z14: Q3
A15: A0014 | B15: Hope Animal Shelter | C15: Islamabad | D15: Bird | E15: Finch | F15: Black & White | G15: Male | H15: 2.7 | I15: 2.5 | J15: Healthy | K15: 2024-09-23 | L15: Born in Shelter | M15: 2024-11-02 | N15: Returned to Owner | O15: 40 | Q15: 0 | R15: 500 | T15: Referral | U15: Yes | V15: Yes | W15: Yes | X15: 2024 | Y15: September | Z15: Q3
A16: A0015 | B16: Second Chance Rescue | C16: Islamabad | D16: Dog | E16: German Shepherd | F16: Spotted | G16: Male | H16: 1.5 | I16: 31.2 | J16: Minor Treatment Needed | K16: 2022-05-20 | L16: Confiscated | M16: 2022-11-09 | N16: Returned to Owner | O16: 173 | Q16: 0 | R16: 1000 | T16: Event | U16: Yes | V16: No | W16: No | X16: 2022 | Y16: May | Z16: Q2
A17: A0016 | B17: Happy Paws Shelter | C17: Islamabad | D17: Rabbit | E17: Mini Rex | F17: Orange | G17: Male | H17: 3.9 | I17: 26.4 | J17: Healthy | K17: 2023-06-28 | L17: Born in Shelter | M17: 2023-10-08 | N17: Adopted | O17: 102 | P17: Family | Q17: 1728 | R17: 500 | S17: Online Transfer | T17: Website | U17: Yes | V17: Yes | W17: No | X17: 2023 | Y17: June | Z17: Q2
A18: A0017 | B18: Hope Animal Shelter | C18: Islamabad | D18: Rabbit | E18: Flemish Giant | F18: Cream | G18: Female | H18: 7.4 | I18: 34.6 | J18: Neutered/Spayed | K18: 2022-11-20 | L18: Stray | M18: 2023-03-13 | N18: Transferred | O18: 113 | Q18: 0 | R18: 0 | T18: Website | U18: Yes | V18: Yes | W18: Yes | X18: 2022 | Y18: November | Z18: Q4
A19: A0018 | B19: City Animal Shelter | C19: Rawalpindi | D19: Cat | E19: Siamese | F19: Gray | G19: Male | H19: 2.5 | I19: 22.4 | J19: Healthy | K19: 2023-07-12 | L19: Confiscated | M19: 2023-09-23 | N19: Returned to Owner | O19: 73 | Q19: 0 | R19: 500 | T19: Referral | U19: Yes | V19: Yes | W19: Yes | X19: 2023 | Y19: July | Z19: Q3
A20: A0019 | B20: Hope Animal Shelter | C20: Karachi | D20: Rabbit | E20: Mini Rex | F20: Cream | G20: Male | H20: 6.8 | I20: 4.4 | J20: Recovering | K20: 2023-06-21 | L20: Abandoned | M20: 2023-08-02 | N20: Fostered | O20: 42 | Q20: 0 | R20: 1000 | T20: Event | U20: Yes | V20: No | W20: No | X20: 2023 | Y20: June | Z20: Q2
A21: A0020 | B21: Happy Paws Shelter | C21: Multan | D21: Dog | E21: Bulldog | F21: Cream | G21: Female | H21: 2.6 | I21: 9.1 | J21: Vaccinated | K21: 2024-01-17 | L21: Confiscated | M21: 2024-01-28 | N21: Euthanized | O21: 11 | Q21: 0 | R21: 0 | T21: Website | U21: Yes | V21: Yes | W21: No | X21: 2024 | Y21: January | Z21: Q1
A22: A0021 | B22: Second Chance Rescue | C22: Quetta | D22: Bird | E22: Parakeet | F22: Brown | G22: Male | H22: 9.6 | I22: 30.3 | J22: Minor Treatment Needed | K22: 2023-01-03 | L22: Stray | M22: 2023-03-30 | N22: Still in Shelter | O22: 86 | Q22: 0 | R22: 0 | T22: Referral | U22: Yes | V22: Yes | W22: No | X22: 2023 | Y22: January | Z22: Q1
A23: A0022 | B23: City Animal Shelter | C23: Multan | D23: Rabbit | E23: Flemish Giant | F23: Cream | G23: Female | H23: 4 | I23: 30.3 | J23: Neutered/Spayed | K23: 2023-04-12 | L23: Born in Shelter | M23: 2023-06-09 | N23: Adopted | O23: 58 | P23: Senior | Q23: 1291 | R23: 500 | S23: Cash | T23: Walk-in | U23: Yes | V23: Yes | W23: No | X23: 2023 | Y23: April | Z23: Q2
A24: A0023 | B24: Happy Paws Shelter | C24: Faisalabad | D24: Dog | E24: German Shepherd | F24: Spotted | G24: Male | H24: 5.3 | I24: 34.5 | J24: Healthy | K24: 2024-06-08 | L24: Stray | M24: 2024-09-05 | N24: Euthanized | O24: 89 | Q24: 0 | R24: 0 | T24: Referral | U24: Yes | V24: No | W24: No | X24: 2024 | Y24: June | Z24: Q2
A25: A0024 | B25: Happy Paws Shelter | C25: Quetta | D25: Rabbit | E25: Dutch | F25: Cream | G25: Female | H25: 7.5 | I25: 23.4 | J25: Neutered/Spayed | K25: 2022-05-24 | L25: Transfer from Another Shelter | M25: 2022-11-11 | N25: Euthanized | O25: 171 | Q25: 0 | R25: 0 | T25: Social Media | U25: No | V25: No | W25: No | X25: 2022 | Y25: May | Z25: Q2
A26: A0025 | B26: Paws & Claws Rescue | C26: Quetta | D26: Cat | E26: Siamese | F26: Tan | G26: Male | H26: 8.2 | I26: 31.6 | J26: Healthy | K26: 2023-01-28 | L26: Abandoned | M26: 2023-05-16 | N26: Still in Shelter | O26: 108 | Q26: 0 | R26: 0 | T26: Website | U26: No | V26: No | W26: No | X26: 2023 | Y26: January | Z26: Q1
A27: A0026 | B27: Hope Animal Shelter | C27: Karachi | D27: Dog | E27: Husky | F27: White | G27: Female | H27: 9.5 | I27: 33.6 | J27: Vaccinated | K27: 2024-06-24 | L27: Confiscated | M27: 2024-12-14 | N27: Returned to Owner | O27: 173 | Q27: 0 | R27: 1000 | T27: Event | U27: Yes | V27: Yes | W27: No | X27: 2024 | Y27: June | Z27: Q2
A28: A0027 | B28: Happy Paws Shelter | C28: Rawalpindi | D28: Cat | E28: Siamese | F28: Tan | G28: Male | H28: 11.8 | I28: 21.6 | J28: Neutered/Spayed | K28: 2023-02-12 | L28: Confiscated | M28: 2023-03-22 | N28: Adopted | O28: 38 | P28: Single Adult | Q28: 1689 | R28: 0 | S28: Bank Deposit | T28: Referral | U28: Yes | V28: Yes | W28: Yes | X28: 2023 | Y28: February | Z28: Q1
A29: A0028 | B29: Second Chance Rescue | C29: Lahore | D29: Cat | E29: Ragdoll | F29: Orange | G29: Male | H29: 6.3 | I29: 2.2 | J29: Recovering | K29: 2024-05-20 | L29: Transfer from Another Shelter | M29: 2024-07-16 | N29: Adopted | O29: 57 | P29: Couple | Q29: 4793 | R29: 2000 | S29: Online Transfer | T29: Referral | U29: No | V29: No | W29: No | X29: 2024 | Y29: May | Z29: Q2
A30: A0029 | B30: Hope Animal Shelter | C30: Peshawar | D30: Dog | E30: Husky | F30: Gray | G30: Female | H30: 9.2 | I30: 18.5 | J30: Healthy | K30: 2024-07-10 | L30: Confiscated | M30: 2024-09-15 | N30: Returned to Owner | O30: 67 | Q30: 0 | R30: 500 | T30: Social Media | U30: Yes | V30: No | W30: No | X30: 2024 | Y30: July | Z30: Q3
A31: A0030 | B31: Happy Paws Shelter | C31: Faisalabad | D31: Rabbit | E31: Lionhead | F31: Tan | G31: Female | H31: 8.4 | I31: 24.9 | J31: Vaccinated | K31: 2022-06-15 | L31: Transfer from Another Shelter | M31: 2022-07-21 | N31: Adopted | O31: 36 | P31: Single Adult | Q31: 1447 | R31: 500 | S31: Cash | T31: Website | U31: No | V31: No | W31: Yes | X31: 2022 | Y31: June | Z31: Q2
A32: A0031 | B32: Furever Home | C32: Peshawar | D32: Dog | E32: Mixed Breed | F32: Orange | G32: Male | H32: 3.7 | I32: 14 | J32: Healthy | K32: 2024-09-03 | L32: Transfer from Another Shelter | M32: 2024-09-05 | N32: Euthanized | O32: 2 | Q32: 0 | R32: 0 | T32: Referral | U32: Yes | V32: No | W32: No | X32: 2024 | Y32: September | Z32: Q3
A33: A0032 | B33: Hope Animal Shelter | C33: Faisalabad | D33: Bird | E33: Cockatiel | F33: Brown | G33: Female | H33: 6.8 | I33: 1.4 | J33: Healthy | K33: 2024-08-15 | L33: Stray | M33: 2024-09-17 | N33: Adopted | O33: 33 | P33: Senior | Q33: 2113 | R33: 1000 | S33: Bank Deposit | T33: Social Media | U33: Yes | V33: No | W33: No | X33: 2024 | Y33: August | Z33: Q3
A34: A0033 | B34: Hope Animal Shelter | C34: Islamabad | D34: Rabbit | E34: Dutch | F34: Black & White | G34: Male | H34: 10 | I34: 16.7 | J34: Neutered/Spayed | K34: 2023-07-24 | L34: Stray | M34: 2023-11-09 | N34: Transferred | O34: 108 | Q34: 0 | R34: 0 | T34: Walk-in | U34: Yes | V34: Yes | W34: No | X34: 2023 | Y34: July | Z34: Q3
A35: A0034 | B35: Hope Animal Shelter | C35: Quetta | D35: Dog | E35: Golden Retriever | F35: Black & White | G35: Male | H35: 6.8 | I35: 8 | J35: Vaccinated | K35: 2023-05-04 | L35: Born in Shelter | M35: 2023-06-06 | N35: Fostered | O35: 33 | Q35: 0 | R35: 0 | T35: Walk-in | U35: Yes | V35: No | W35: Yes | X35: 2023 | Y35: May | Z35: Q2
A36: A0035 | B36: Happy Paws Shelter | C36: Peshawar | D36: Dog | E36: Labrador | F36: White | G36: Female | H36: 4.8 | I36: 25.2 | J36: Recovering | K36: 2023-10-01 | L36: Confiscated | M36: 2024-02-26 | N36: Still in Shelter | O36: 148 | Q36: 0 | R36: 0 | T36: Event | U36: Yes | V36: No | W36: Yes | X36: 2023 | Y36: October | Z36: Q4
A37: A0036 | B37: Happy Paws Shelter | C37: Faisalabad | D37: Rabbit | E37: Lionhead | F37: Orange | G37: Male | H37: 0.9 | I37: 22.8 | J37: Minor Treatment Needed | K37: 2024-05-27 | L37: Abandoned | M37: 2024-11-13 | N37: Euthanized | O37: 170 | Q37: 0 | R37: 0 | T37: Referral | U37: Yes | V37: No | W37: No | X37: 2024 | Y37: May | Z37: Q2
A38: A0037 | B38: City Animal Shelter | C38: Multan | D38: Cat | E38: Mixed Breed | F38: Golden | G38: Male | H38: 5.3 | I38: 25.7 | J38: Healthy | K38: 2023-07-08 | L38: Transfer from Another Shelter | M38: 2023-12-13 | N38: Fostered | O38: 158 | Q38: 0 | R38: 1000 | T38: Website | U38: No | V38: No | W38: No | X38: 2023 | Y38: July | Z38: Q3
A39: A0038 | B39: City Animal Shelter | C39: Quetta | D39: Rabbit | E39: Holland Lop | F39: Cream | G39: Male | H39: 4.3 | I39: 9.4 | J39: Vaccinated | K39: 2024-10-09 | L39: Owner Surrender | M39: 2024-12-31 | N39: Adopted | O39: 84 | P39: Individual | Q39: 2497 | R39: 0 | S39: Card | T39: Referral | U39: No | V39: No | W39: No | X39: 2024 | Y39: October | Z39: Q4
A40: A0039 | B40: Hope Animal Shelter | C40: Multan | D40: Dog | E40: Husky | F40: Orange | G40: Female | H40: 4.9 | I40: 8.9 | J40: Minor Treatment Needed | K40: 2024-07-06 | L40: Confiscated | M40: 2024-07-11 | N40: Adopted | O40: 5 | P40: Couple | Q40: 5410 | R40: 0 | S40: Online Transfer | T40: Social Media | U40: No | V40: No | W40: No | X40: 2024 | Y40: July | Z40: Q3
...

Sheet Cleaned data
A1: Animal_ID | B1: Shelter_Name | C1: City | D1: Species | E1: Breed | F1: Color | G1: Gender | H1: Age_Years | I1: Weight_KG | J1: Health_Status | K1: Intake_Date | L1: Intake_Reason | M1: Outcome_Date | N1: Outcome_Type | O1: Days_In_Shelter | P1: Adopter_Type | Q1: Adoption_Fee_PKR | R1: Donation_Amount_PKR | S1: Payment_Method | T1: Source_of_Inquiry | U1: Vaccinated | V1: Neutered_Spayed | W1: Microchipped | X1: Year | Y1: Month | Z1: Quarter
A2: A0001 | B2: Paws & Claws Rescue | C2: Lahore | D2: Cat | E2: Persian | F2: Spotted | G2: Female | H2: 8.9 | I2: 23.8 | J2: Healthy | K2: 2023-07-18 | L2: Stray | M2: 2023-09-19 | N2: Returned to Owner | O2: 63 | P2: N/A | Q2: 0 | R2: 0 | S2: N/A | T2: Walk-in | U2: Yes | V2: Yes | W2: Yes | X2: 2023 | Y2: July | Z2: Q3
A3: A0002 | B3: Second Chance Rescue | C3: Faisalabad | D3: Cat | E3: Siamese | F3: Black & White | G3: Female | H3: 9.7 | I3: 0.7 | J3: Healthy | K3: 2024-05-09 | L3: Owner Surrender | M3: 2024-07-05 | N3: Fostered | O3: 57 | P3: N/A | Q3: 0 | R3: 500 | S3: N/A | T3: Social Media | U3: Yes | V3: Yes | W3: No | X3: 2024 | Y3: May | Z3: Q2
A4: A0003 | B4: Paws & Claws Rescue | C4: Lahore | D4: Cat | E4: Bengal | F4: Tan | G4: Male | H4: 9.7 | I4: 25.7 | J4: Vaccinated | K4: 2023-12-06 | L4: Abandoned | M4: 2024-05-09 | N4: Transferred | O4: 155 | P4: N/A | Q4: 0 | R4: 0 | S4: N/A | T4: Event | U4: Yes | V4: No | W4: No | X4: 2023 | Y4: December | Z4: Q4
A5: A0004 | B5: Hope Animal Shelter | C5: Multan | D5: Cat | E5: Persian | F5: Brown | G5: Female | H5: 1.3 | I5: 10.1 | J5: Healthy | K5: 2023-04-12 | L5: Owner Surrender | M5: 2023-06-26 | N5: Adopted | O5: 75 | P5: Senior | Q5: 2453 | R5: 5000 | S5: Cash | T5: Event | U5: Yes | V5: No | W5: No | X5: 2023 | Y5: April | Z5: Q2
A6: A0005 | B6: Second Chance Rescue | C6: Islamabad | D6: Dog | E6: Husky | F6: Black & White | G6: Female | H6: 10.1 | I6: 27.3 | J6: Healthy | K6: 2024-02-17 | L6: Stray | M6: 2024-04-27 | N6: Returned to Owner | O6: 70 | P6: N/A | Q6: 0 | R6: 500 | S6: N/A | T6: Website | U6: Yes | V6: Yes | W6: No | X6: 2024 | Y6: February | Z6: Q1
A7: A0006 | B7: Paws & Claws Rescue | C7: Faisalabad | D7: Bird | E7: Lovebird | F7: Spotted | G7: Female | H7: 6.8 | I7: 9.6 | J7: Healthy | K7: 2022-10-20 | L7: Owner Surrender | M7: 2022-12-27 | N7: Adopted | O7: 68 | P7: Family | Q7: 1510 | R7: 2000 | S7: Bank Deposit | T7: Walk-in | U7: Yes | V7: Yes | W7: No | X7: 2022 | Y7: October | Z7: Q4
A8: A0007 | B8: City Animal Shelter | C8: Islamabad | D8: Dog | E8: Mixed Breed | F8: White | G8: Female | H8: 7.2 | I8: 16.6 | J8: Recovering | K8: 2022-05-11 | L8: Confiscated | M8: 2022-08-18 | N8: Still in Shelter | O8: 99 | P8: N/A | Q8: 0 | R8: 0 | S8: N/A | T8: Social Media | U8: Yes | V8: No | W8: No | X8: 2022 | Y8: May | Z8: Q2
A9: A0008 | B9: Hope Animal Shelter | C9: Peshawar | D9: Dog | E9: Husky | F9: Brown | G9: Female | H9: 10.5 | I9: 10.8 | J9: Recovering | K9: 2022-01-07 | L9: Owner Surrender | M9: 2022-03-16 | N9: Adopted | O9: 68 | P9: Couple | Q9: 7158 | R9: 0 | S9: Cash | T9: Event | U9: Yes | V9: No | W9: Yes | X9: 2022 | Y9: January | Z9: Q1
A10: A0009 | B10: Furever Home | C10: Lahore | D10: Cat | E10: Bengal | F10: Cream | G10: Male | H10: 11.4 | I10: 3.5 | J10: Healthy | K10: 2023-09-22 | L10: Confiscated | M10: 2023-11-23 | N10: Adopted | O10: 62 | P10: Single Adult | Q10: 2486 | R10: 1000 | S10: Card | T10: Social Media | U10: No | V10: Yes | W10: No | X10: 2023 | Y10: September | Z10: Q3
A11: A0010 | B11: Happy Paws Shelter | C11: Peshawar | D11: Cat | E11: Domestic Shorthair | F11: Spotted | G11: Male | H11: 3.1 | I11: 2.7 | J11: Healthy | K11: 2024-02-04 | L11: Stray | M11: 2024-05-27 | N11: Fostered | O11: 113 | P11: N/A | Q11: 0 | R11: 0 | S11: N/A | T11: Walk-in | U11: Yes | V11: Yes | W11: Yes | X11: 2024 | Y11: February | Z11: Q1
A12: A0011 | B12: Second Chance Rescue | C12: Rawalpindi | D12: Rabbit | E12: Holland Lop | F12: Golden | G12: Female | H12: 8.1 | I12: 7.9 | J12: Recovering | K12: 2024-11-18 | L12: Transfer from Another Shelter | M12: 2024-12-31 | N12: Transferred | O12: 61 | P12: N/A | Q12: 0 | R12: 0 | S12: N/A | T12: Website | U12: Yes | V12: Yes | W12: No | X12: 2024 | Y12: November | Z12: Q4
A13: A0012 | B13: Happy Paws Shelter | C13: Peshawar | D13: Rabbit | E13: Dutch | F13: Golden | G13: Male | H13: 4.9 | I13: 12.2 | J13: Vaccinated | K13: 2024-04-21 | L13: Transfer from Another Shelter | M13: 2024-08-19 | N13: Adopted | O13: 120 | P13: Family | Q13: 903 | R13: 0 | S13: Bank Deposit | T13: Website | U13: Yes | V13: No | W13: No | X13: 2024 | Y13: April | Z13: Q2
... A1201: A1200 | B1201: City Animal Shelter | C1201: Lahore | D1201: Dog | E1201: Golden Retriever | F1201: Brown | G1201: Male | H1201: 9.5 | I1201: 34 | J1201: Healthy | K1201: 2022-09-19 | L1201: Born in Shelter | M1201: 2022-12-30 | N1201: Adopted | O1201: 102 | P1201: Individual | Q1201: 5856 | R1201: 0 | S1201: Online Transfer | T1201: Referral | U1201: No | V1201: Yes | W1201: Yes | X1201: 2022 | Y1201: September | Z1201: Q3

Sheet Functions
A1: Use of XLOOKUP and VLOOKUP and Other Functions
A2: Enter the animal id | B2: Breed | C2: Health status | D2: Status | E2: Age
A3: A0003 | B3: =VLOOKUP(A3,'Cleaned data'!$A:$Y,5,0) -> Bengal | C3: =VLOOKUP(A3,'Cleaned data'!$A:$Y,10,0) -> Vaccinated | D3: =VLOOKUP(A3,'Cleaned data'!$A:$Y,10,0) -> Vaccinated | E3: =_xlfn.XLOOKUP(A3,'Cleaned data'!$A:$A,'Cleaned data'!$H:$H,"Not Found") -> 9.7 | H3: SUMMARY | I3: Amounts | J3: FUNCTIONS
A4: A0004 | B4: =VLOOKUP(A4,'Cleaned data'!$A:$Y,5,0) -> Persian | C4: =VLOOKUP(A4,'Cleaned data'!$A:$Y,10,0) -> Healthy | D4: =VLOOKUP(A4,'Cleaned data'!$A:$Y,10,0) -> Healthy | E4: =_xlfn.XLOOKUP(A4,'Cleaned data'!$A:$A,'Cleaned data'!$H:$H,"Not Found") -> 1.3 | H4: Total Adoption money | I4: =SUM('Cleaned data'!Q:Q) -> 1870835 | J4: \\countif
A5: A0005 | B5: =VLOOKUP(A5,'Cleaned data'!$A:$Y,5,0) -> Husky | C5: =VLOOKUP(A5,'Cleaned data'!$A:$Y,10,0) -> Healthy | D5: =VLOOKUP(A5,'Cleaned data'!$A:$Y,10,0) -> Healthy | E5: =_xlfn.XLOOKUP(A5,'Cleaned data'!$A:$A,'Cleaned data'!$H:$H,"Not Found") -> 10.1 | H5: Total Donation money | I5: =SUM('Cleaned data'!R:R) -> 687500
A6: A0006 | B6: =VLOOKUP(A6,'Cleaned data'!$A:$Y,5,0) -> Lovebird | C6: =VLOOKUP(A6,'Cleaned data'!$A:$Y,10,0) -> Healthy | D6: =VLOOKUP(A6,'Cleaned data'!$A:$Y,10,0) -> Healthy | E6: =_xlfn.XLOOKUP(A6,'Cleaned data'!$A:$A,'Cleaned data'!$H:$H,"Not Found") -> 6.8 | H6: Total Healthy Pets | I6: =COUNTIF('Cleaned data'!J:J, "Healthy") -> 560 | J6: \\countif
A7: A0007 | B7: =VLOOKUP(A7,'Cleaned data'!$A:$Y,5,0) -> Mixed Breed | C7: =VLOOKUP(A7,'Cleaned data'!$A:$Y,10,0) -> Recovering | D7: =VLOOKUP(A7,'Cleaned data'!$A:$Y,10,0) -> Recovering | E7: =_xlfn.XLOOKUP(A7,'Cleaned data'!$A:$A,'Cleaned data'!$H:$H,"Not Found") -> 7.2 | H7: Total Adopted pets | I7: =COUNTIF('Cleaned data'!N:N, "Adopted") -> 459 | J7: \\sum
A8: A0008 | B8: =VLOOKUP(A8,'Cleaned data'!$A:$Y,5,0) -> Husky | C8: =VLOOKUP(A8,'Cleaned data'!$A:$Y,10,0) -> Recovering | D8: =VLOOKUP(A8,'Cleaned data'!$A:$Y,10,0) -> Recovering | E8: =_xlfn.XLOOKUP(A8,'Cleaned data'!$A:$A,'Cleaned data'!$H:$H,"Not Found") -> 10.5 | H8: Total Pets returned to Owners | I8: =COUNTIF('Cleaned data'!N:N, "Returned to Owner") -> 173 | J8: \\countif
A9: A0009 | B9: =VLOOKUP(A9,'Cleaned data'!$A:$Y,5,0) -> Bengal | C9: =VLOOKUP(A9,'Cleaned data'!$A:$Y,10,0) -> Healthy | D9: =VLOOKUP(A9,'Cleaned data'!$A:$Y,10,0) -> Healthy | E9: =_xlfn.XLOOKUP(A9,'Cleaned data'!$A:$A,'Cleaned data'!$H:$H,"Not Found") -> 11.4 | H9: Total Pets Adopted by Couples | I9: =COUNTIFS('Cleaned data'!P:P, "Couple", 'Cleaned data'!N:N,"Adopted") -> 101 | J9: \\countifs
A10: A0010 | B10: =VLOOKUP(A10,'Cleaned data'!$A:$Y,5,0) -> Domestic Shorthair | C10: =VLOOKUP(A10,'Cleaned data'!$A:$Y,10,0) -> Healthy | D10: =VLOOKUP(A10,'Cleaned data'!$A:$Y,10,0) -> Healthy | E10: =_xlfn.XLOOKUP(A10,'Cleaned data'!$A:$A,'Cleaned data'!$H:$H,"Not Found") -> 3.1 | H10: Total Pets Adopted in Lahore | I10: =COUNTIFS('Cleaned data'!C:C,"Lahore",'Cleaned data'!N:N, "Adopted") -> 71 | J10: \\countifs
A11: A0011 | B11: =VLOOKUP(A11,'Cleaned data'!$A:$Y,5,0) -> Holland Lop | C11: =VLOOKUP(A11,'Cleaned data'!$A:$Y,10,0) -> Recovering | D11: =VLOOKUP(A11,'Cleaned data'!$A:$Y,10,0) -> Recovering | E11: =_xlfn.XLOOKUP(A11,'Cleaned data'!$A:$A,'Cleaned data'!$H:$H,"Not Found") -> 8.1
A12: A0012 | B12: =VLOOKUP(A12,'Cleaned data'!$A:$Y,5,0) -> Dutch | C12: =VLOOKUP(A12,'Cleaned data'!$A:$Y,10,0) -> Vaccinated | D12: =VLOOKUP(A12,'Cleaned data'!$A:$Y,10,0) -> Vaccinated | E12: =_xlfn.XLOOKUP(A12,'Cleaned data'!$A:$A,'Cleaned data'!$H:$H,"Not Found") -> 4.9
A13: A0013 | B13: =VLOOKUP(A13,'Cleaned data'!$A:$Y,5,0) -> Domestic Shorthair | C13: =VLOOKUP(A13,'Cleaned data'!$A:$Y,10,0) -> Healthy | D13: =VLOOKUP(A13,'Cleaned data'!$A:$Y,10,0) -> Healthy | E13: =_xlfn.XLOOKUP(A13,'Cleaned data'!$A:$A,'Cleaned data'!$H:$H,"Not Found") -> 10.2
A14: A0014 | B14: =VLOOKUP(A14,'Cleaned data'!$A:$Y,5,0) -> Finch | C14: =VLOOKUP(A14,'Cleaned data'!$A:$Y,10,0) -> Healthy | D14: =VLOOKUP(A14,'Cleaned data'!$A:$Y,10,0) -> Healthy | E14: =_xlfn.XLOOKUP(A14,'Cleaned data'!$A:$A,'Cleaned data'!$H:$H,"Not Found") -> 2.7
A15: A0015 | B15: =VLOOKUP(A15,'Cleaned data'!$A:$Y,5,0) -> German Shepherd | C15: =VLOOKUP(A15,'Cleaned data'!$A:$Y,10,0) -> Minor Treatment Needed | D15: =VLOOKUP(A15,'Cleaned data'!$A:$Y,10,0) -> Minor Treatment Needed | E15: =_xlfn.XLOOKUP(A15,'Cleaned data'!$A:$A,'Cleaned data'!$H:$H,"Not Found") -> 1.5
A16: A0016 | B16: =VLOOKUP(A16,'Cleaned data'!$A:$Y,5,0) -> Mini Rex | C16: =VLOOKUP(A16,'Cleaned data'!$A:$Y,10,0) -> Healthy | D16: =VLOOKUP(A16,'Cleaned data'!$A:$Y,10,0) -> Healthy | E16: =_xlfn.XLOOKUP(A16,'Cleaned data'!$A:$A,'Cleaned data'!$H:$H,"Not Found") -> 3.9
A17: A0017 | B17: =VLOOKUP(A17,'Cleaned data'!$A:$Y,5,0) -> Flemish Giant | C17: =VLOOKUP(A17,'Cleaned data'!$A:$Y,10,0) -> Neutered/Spayed | D17: =VLOOKUP(A17,'Cleaned data'!$A:$Y,10,0) -> Neutered/Spayed | E17: =_xlfn.XLOOKUP(A17,'Cleaned data'!$A:$A,'Cleaned data'!$H:$H,"Not Found") -> 7.4
A18: A0018 | B18: =VLOOKUP(A18,'Cleaned data'!$A:$Y,5,0) -> Siamese | C18: =VLOOKUP(A18,'Cleaned data'!$A:$Y,10,0) -> Healthy | D18: =VLOOKUP(A18,'Cleaned data'!$A:$Y,10,0) -> Healthy | E18: =_xlfn.XLOOKUP(A18,'Cleaned data'!$A:$A,'Cleaned data'!$H:$H,"Not Found") -> 2.5
A19: A0019 | B19: =VLOOKUP(A19,'Cleaned data'!$A:$Y,5,0) -> Mini Rex | C19: =VLOOKUP(A19,'Cleaned data'!$A:$Y,10,0) -> Recovering | D19: =VLOOKUP(A19,'Cleaned data'!$A:$Y,10,0) -> Recovering | E19: =_xlfn.XLOOKUP(A19,'Cleaned data'!$A:$A,'Cleaned data'!$H:$H,"Not Found") -> 6.8

Sheet Pivot charts and tables
A1: Row Labels | B1: Count of Shelter_Name
A2: Faisalabad | B2: 143
A3: Islamabad | B3: 154
A4: Karachi | B4: 128
A5: Lahore | B5: 166
A6: Multan | B6: 164
A7: Peshawar | B7: 141
A8: Quetta | B8: 157
A9: Rawalpindi | B9: 147
A10: Grand Total | B10: 1200
A18: Row Labels | B18: Count of Breed
A19: Black | B19: 117
A20: Bird | B20: 12
A21: Cat | B21: 29
A22: Dog | B22: 58
A23: Rabbit | B23: 18
A24: Black & White | B24: 121
A25: Bird | B25: 15
A26: Cat | B26: 35
A27: Dog | B27: 56
A28: Rabbit | B28: 15
A29: Brown | B29: 129
A30: Bird | B30: 17
... A69: Grand Total | B69: 1200
A74: Row Labels | B74: Count of Adopter_Type
A75: Couple | B75: 101
A76: Family | B76: 94
A77: Individual | B77: 91
A78: N/A | B78: 741
A79: Senior | B79: 83
A80: Single Adult | B80: 90
A81: Grand Total | B81: 1200
A87: Row Labels | B87: Count of Payment_Method
A88: Bank Deposit | B88: 117
A89: Faisalabad | B89: 11
A90: Islamabad | B90: 15
A91: Karachi | B91: 9
A92: Lahore | B92: 14
A93: Multan | B93: 22
A94: Peshawar | B94: 14
...

Sheet Dashboard
A1: PETS SHELTER PERFORMANCE ANALYSIS DASHBOARD
N9: 💰 TOTAL ADOPTION MONEY | Q9: 💰 TOTAL DONATION MONEY | T9: 📈 TOTAL HEALTHY PETS | W9: 📈 TOTAL ADOPTED PETS
N10: =SUM('Cleaned data'!Q:Q) -> 1870835 | Q10: =SUM('Cleaned data'!R:R) -> 687500 | T10: =COUNTIF('Cleaned data'!J:J, "Healthy") -> 560 | W10: =COUNTIF('Cleaned data'!N:N, "Adopted") -> 459
